auth_test.py::SubmissionTest::test_submitting_batch_date_num
--------------------------------------------------------------------
Last Page: http://127.0.0.1:8000/accounts/profile/
  Browser: firefox (104.0.2)
   Driver: geckodriver (0.31.0)
Timestamp: 1663916567  (Unix Timestamp)
     Date: Friday, September 23, 2022
     Time: 1:02:47 AM  (MDT, UTC-07:00)
--------------------------------------------------------------------
Traceback: File "/opt/homebrew/Cellar/python@3.10/3.10.6_1/Frameworks/Python.framework/Versions/3.10/lib/python3.10/unittest/case.py", line 591, in run
    self._callTestMethod(testMethod)
  File "/opt/homebrew/Cellar/python@3.10/3.10.6_1/Frameworks/Python.framework/Versions/3.10/lib/python3.10/unittest/case.py", line 549, in _callTestMethod
    method()
  File "/Users/collinjones/Desktop/bandnames.cool/main/tests/auth_test.py", line 40, in test_submitting_batch_date_num
    self.assert_true(bn1=="Test A")
  File "/opt/homebrew/lib/python3.10/site-packages/seleniumbase/fixtures/base_case.py", line 6187, in assert_true
    self.assertTrue(expr, msg=msg)
  File "/opt/homebrew/Cellar/python@3.10/3.10.6_1/Frameworks/Python.framework/Versions/3.10/lib/python3.10/unittest/case.py", line 687, in assertTrue
    raise self.failureException(msg)
Exception: False is not true